Workbook
Name テストケース数シート別: 'テスト仕様（No.1)'!$C$1
Name テストケース数シート別: 'テスト仕様（No.2)'!$C$1
Name テストケース数シート別: 'テスト仕様（No.3)'!$C$1
Name テストケース数シート別: #REF!

Sheet 表紙
AQ1: 管理No.：
A4: 単体テスト仕様書兼結果報告書 （第1.0版）
A14: 顧客ID | H14: － | X14: 顧客名 | AD14: ホクレン
A15: システムID | H15: － | X15: システム名 | AD15: 統合会計システム
A16: サブシステムID | H16: － | X16: サブシステム名 | AD16: －
A17: 機能ID | H17: 8.6.4 | X17: 機能名 | AD17: 手数料配分計算書出力
A18: プログラムID | H18: － | X18: プログラム名 | AD18: －
A19: 作成日付 | H19: YYYY/MM/DD | X19: 作成者 | AD19: XXXXXXXXXX
A20: 最終変更日付 | H20: YYYY/MM/DD | X20: 変更者 | AD20: XXXXXXXXXX
L25: 確認欄
L27: 印 | Q27: 印 | V27: 印 | AA27: 印 | AF27: 印

Sheet 改訂履歴
A1: No. | B1: 版 | C1: 変更箇所 | D1: 変更内容 | E1: 管理番号 | F1: 変更者 ・日付 | G1: 確認者 ・日付 | H1: 承認者 ・日付
A2: =ROW()-1 -> 1
A4: 2
A6: 3
A8: 4
A10: 5
A12: 6
A14: 7
A16: 8
A18: 9
A20: 10

Sheet テスト一覧
B1: No. | C1: テスト観点 | D1: 前提条件 | E1: 確認項目 ※詳細は「単体テスト観点」を参照 | F1: 想定結果 | G1: エビデンス | H1: 確認結果 | I1: テストパターン数 | J1: テストパターン数合計
B2: 1 | C2: DAO+Mapperのメソッドの妥当性 選択可能業種取得 | D2: JUnitで確認 | E2: ・Mapperの処理分岐 ・SELECT文のSELECT句 ・SELECT文のWHERE句 ・SELECT文の結合条件(JOIN) ・SELECT文の集約条件 (GROUP BY) ・SELECT文のORDER BY句 | F2: ・メソッドが内部設計通りに動作すること | I2: {=INDIRECT("'テスト仕様(No." & B2 & ")'!$E$1")} -> 5 | J2: =SUM(I2:I3) -> 10
B3: 2 | C3: DAO+Mapperのメソッドの妥当性 全道共計手数料配分計算書情報検索 | D3: JUnitで確認 | E3: ・Mapperの処理分岐 ・SELECT文のSELECT句 ・SELECT文のWHERE句 ・SELECT文の結合条件(JOIN) ・SELECT文の集約条件 (GROUP BY) ・SELECT文のORDER BY句 | F3: ・メソッドが内部設計通りに動作すること | I3: {=INDIRECT("'テスト仕様(No." & B3 & ")'!$E$1")} -> 5
B4: 3 | C4: DAO+Mapperのメソッドの妥当性 購買手数料配分情報情報検索 | D4: JUnitで確認 | E4: ・Mapperの処理分岐 ・SELECT文のSELECT句 ・SELECT文のWHERE句 ・SELECT文の結合条件(JOIN) ・SELECT文の集約条件 (GROUP BY) ・SELECT文のORDER BY句 | F4: ・メソッドが内部設計通りに動作すること | I4: {=INDIRECT("'テスト仕様(No." & B4 & ")'!$E$1")} -> 5

Sheet テスト仕様（No.1)
B1: テストケースＮｏ． | C1: 1 | D1: 件数： | E1: =COUNTA(F1:CU1) -> 5 | F1: =COLUMN()-5 -> 1 | G1: =COLUMN()-5 -> 2 | H1: =COLUMN()-5 -> 3 | I1: =COLUMN()-5 -> 4 | J1: =COLUMN()-5 -> 5
C2: № | D2: テストケース条件内容
B3: テストケース条件 | C3: 1 | D3: parameterType
C4: =C3+1 -> 2 | D4: 組織コード
C5: 3 | D5: NULL以外 | F5: Y | H5: Y | I5: Y | J5: Y
C6: 4 | D6: NULL | G6: Y
C9: № | D9: 確認項目内容
C10: 1 | D10: resultType
C11: 2 | D11: テストデータ期待値（No.1）シートTC01 の処理結果照会Dtoと同様のデータが返却されること | F11: Y
C12: 3 | D12: テストデータ期待値（No.1）シートTC02 の処理結果照会Dtoと同様のデータが返却されること | G12: Y
C13: 4 | D13: テストデータ期待値（No.1）シートTC03 の処理結果照会Dtoと同様のデータが返却されること | H13: Y
C14: 5 | D14: テストデータ期待値（No.1）シートTC04 の処理結果照会Dtoと同様のデータが返却されること | I14: Y
C15: 6 | D15: テストデータ期待値（No.1）シートTC05 の処理結果照会Dtoと同様のデータが返却されること | J15: Y
C19: № | D19: エビデンス内容
B20: エビデンス | C20: 1 | E20: I
E21: O
E22: I
E23: O
E24: I
E25: O
E26: I
E27: O
E28: I
E29: O
E30: I
E31: O
E32: I
... E35: O

Sheet テストデータDB（No.1）
B5: 組織／業種マスタ(DAA447_SoshikiGyoshuMst)
B6: 項目名称（日本語） | C6: 削除区分 | D6: 排他カウンタ | E6: 作成日時 | F6: 最終更新日時 | G6: 最終更新者ユーザーＩＤ | H6: 入力日時 | I6: 入力者ユーザーＩＤ | J6: 承認日時 | K6: 承認者ユーザーＩＤ | L6: 組織コード | M6: 業種コード | N6: 適用開始日 | O6: 適用終了日 | P6: 申請番号 | Q6: 備考
B7: 項目名称（英字）＊ | C7: SAKZYO_KBN | D7: HAITA_CNT | E7: SAKSE_DTM | F7: LSTUPD_DTM | G7: LSTUPD_USER_ID | H7: NYURYOKU_DTM | I7: NYURYOKU_USER_ID | J7: SHONIN_DTM | K7: SHONIN_USER_ID | L7: SOSHIKI_CD | M7: GYOSHU_CD | N7: TEKIYO_KAISHIBI | O7: TEKIYO_SHURYOBI | P7: SHINSEI_NO
B8: データ型 | C8: CHAR | D8: INTEGER | E8: TIMESTAMP | F8: TIMESTAMP | G8: VARCHAR | H8: TIMESTAMP | I8: VARCHAR | J8: TIMESTAMP | K8: VARCHAR | L8: VARCHAR | M8: VARCHAR | N8: INTEGER | O8: INTEGER | P8: VARCHAR
B9: 桁数 | C9: 1 | G9: 8 | I9: 8 | K9: 8 | L9: 4 | M9: 2 | N9: 8 | O9: 8 | P9: 20
B10: 小数点以下 | N10: 0 | O10: 0
B11: 符号
B12: Pｷｰ* | L12: 1 | M12: 2 | N12: 3
B13: 初期値* | C13: 0 | D13: 0 | O13: 99991231
B14: NN* | C14: Y | D14: Y | E14: Y | F14: Y | G14: Y | H14: Y | I14: Y | L14: Y | M14: Y | N14: Y | O14: Y | P14: Y
B15: TC01~05 | C15: 0 | D15: 0 | E15: 2025-04-01-08.30.00.000000 | F15: 2025-04-01-08.30.00.000000 | G15: USR00001 | H15: 2025-04-01-08.20.00.000000 | I15: USR00001 | J15: 2025-04-01-09.10.00.000000 | K15: APR00001 | L15: 1010 | M15: 01 | N15: 20250404 | O15: 20261201 | P15: WF20250401000001 | Q15: 基準日: between 適用開始日 and 適用終了日 適用開始日 -1 日 適用終了日 +1 日 = 適用開始日 = 適用終了日
B16: TC01 | C16: 0 | D16: 0 | E16: 2025-04-01-08.30.00.000000 | F16: 2025-04-01-08.30.00.000000 | G16: USR00001 | H16: 2025-04-01-08.20.00.000000 | I16: USR00001 | J16: 2025-04-01-09.10.00.000000 | K16: APR00001 | L16: 1010 | M16: 01 | N16: 20250405 | O16: 20261201 | P16: WF20250401000001 | Q16: Group by
B17: TC01 | C17: 0 | D17: 0 | E17: 2025-04-01-08.30.00.000000 | F17: 2025-04-01-08.30.00.000000 | G17: USR00001 | H17: 2025-04-01-08.20.00.000000 | I17: USR00001 | J17: 2025-04-01-09.10.00.000000 | K17: APR00001 | L17: 1010 | M17: 02 | N17: 20250406 | O17: 20261201 | P17: WF20250401000001 | Q17: Group by
B18: TC01 | C18: 0 | D18: 0 | E18: 2025-04-01-08.30.00.000000 | F18: 2025-04-01-08.30.00.000000 | G18: USR00001 | H18: 2025-04-01-08.20.00.000000 | I18: USR00001 | J18: 2025-04-01-09.10.00.000000 | K18: APR00001 | L18: 1010 | M18: 02 | N18: 20250407 | O18: 20261201 | P18: WF20250401000001 | Q18: Group by

Sheet テストデータ期待値（No.1)
B4: 入力 | C4: java.util.Map
B5: ケースNo | C5: 組織コード | D5: 基準日
B6: caseNo | C6: soshikiCd
B7: TC01 | C7: 1010 | D7: 20250501 | E7: TC01
B8: TC02 | C8: NULL | D8: 20250403 | E8: TC02_1
B9: TC03 | C9: 1010 | D9: 20261202 | E9: TC02_2
B10: TC04 | C10: 1010 | D10: 20250404 | E10: TC02_3
B11: TC05 | C11: 1010 | D11: 20261201 | E11: TC02_4
B16: 期待値 | C16: String
B17: ケースNo | C17: 業種コード
B18: caseNo | C18: soshikiCd
B19: TC01 | C19: 01,02
B20: TC02 | C20: NULL
B21: TC03 | C21: NULL
B22: TC04 | C22: NULL
B23: TC05 | C23: NULL

Sheet テスト仕様（No.2)
B1: テストケースＮｏ． | C1: 1 | D1: 件数： | E1: =COUNTA(F1:CV1) -> 5 | F1: =COLUMN()-5 -> 1 | G1: =COLUMN()-5 -> 2 | H1: =COLUMN()-5 -> 3 | I1: =COLUMN()-5 -> 4 | J1: =COLUMN()-5 -> 5
C2: № | D2: テストケース条件内容
B3: テストケース条件 | C3: 1 | D3: parameterType
C4: =C3+1 -> 2 | D4: 業種コード
C5: 3 | D5: NULL以外 | F5: Y | J5: Y
C6: 4 | D6: NULL | G6: Y | H6: Y | I6: Y
C8: 5 | D8: 所属コード
C9: 6 | D9: 経理部以外 | F9: Y | G9: Y | I9: Y | J9: Y
C10: 7 | D10: 経理部("1") | H10: Y
C14: № | D14: 確認項目内容
C15: 1 | D15: resultType
C16: 3 | D16: テストデータ期待値（No.1）シートTC01 の処理結果照会Dtoと同様のデータが返却されること | F16: Y
C17: 4 | D17: テストデータ期待値（No.1）シートTC02 の処理結果照会Dtoと同様のデータが返却されること | G17: Y
C18: 5 | D18: テストデータ期待値（No.1）シートTC03 の処理結果照会Dtoと同様のデータが返却されること | H18: Y
C19: 6 | D19: テストデータ期待値（No.1）シートTC04 の処理結果照会Dtoと同様のデータが返却されること | I19: Y
C20: 7 | D20: テストデータ期待値（No.1）シートTC05 の処理結果照会Dtoと同様のデータが返却されること | J20: Y
C24: № | D24: エビデンス内容
B25: エビデンス | C25: 1 | E25: I
E26: O
E27: I
E28: O
E29: I
E30: O
E31: I
E32: O
E33: I
E34: O
E35: I
E36: O
E37: I
... E40: O

Sheet テストデータDB（No.2）
B5: 販売共計手数料配分計算データ(DAC321_HanbaiKyokeiTesuryoHaibunKeisanData)
B6: 項目名称（日本語） | C6: 削除区分 | D6: 排他カウンタ | E6: 作成日時 | F6: 最終更新日時 | G6: 最終更新者ユーザーＩＤ | H6: 会計年度 | I6: 対象年月 | J6: 業種コード | K6: 収支管理品目コード | L6: 年産 | M6: 共計次数 | N6: 配分箇所コード | O6: 共計組織コード | P6: 取扱高金額月計 | Q6: 取扱高手数料月計 | R6: 取扱高金額累計 | S6: 取扱高手数料累計
B7: 項目名称（英字）＊ | C7: SAKZYO_KBN | D7: HAITA_CNT | E7: SAKSE_DTM | F7: LSTUPD_DTM | G7: LSTUPD_USER_ID | H7: KAIKEI_NENDO | I7: TAISHO_NENGETSU | J7: GYOSHU_CD | K7: SHUSHI_KANRI_HINMOKU_CD | L7: NENSAN | M7: KYOKEI_JISU | N7: HAIBUN_KASHO_CD | O7: KYOKEI_SOSHIKI_CD | P7: TORIATSUKAIDAKA_KINGAKU_GEKKEI | Q7: TORIATSUKAIDAKA_TESURYO_GEKKEI | R7: TORIATSUKAIDAKA_KINGAKU_RUIKEI | S7: TORIATSUKAIDAKA_TESURYO_RUIKEI
B8: データ型 | C8: CHAR | D8: INTEGER | E8: TIMESTAMP | F8: TIMESTAMP | G8: VARCHAR | H8: NUMERIC | I8: NUMERIC | J8: VARCHAR | K8: VARCHAR | L8: VARCHAR | M8: VARCHAR | N8: VARCHAR | O8: VARCHAR | P8: NUMERIC | Q8: NUMERIC | R8: NUMERIC | S8: NUMERIC
B9: 桁数 | C9: 1 | G9: 8 | H9: 4 | I9: 6 | J9: 2 | K9: 6 | L9: 4 | M9: 2 | N9: 2 | O9: 4 | P9: 13 | Q9: 13 | R9: 13 | S9: 13
B10: 小数点以下
B11: 符号
B12: Pｷｰ* | H12: 1 | I12: 2 | J12: 3 | K12: 4 | L12: 5 | M12: 6 | N12: 7 | O12: 8
B13: 初期値* | C13: 0 | D13: 0
B14: NN* | C14: Y | D14: Y | E14: Y | F14: Y | G14: Y | H14: Y | I14: Y | J14: Y | K14: Y | L14: Y | M14: Y
B15: TC01`05 | C15: 0 | D15: 0 | E15: 2026-05-13-09.38.30.090000 | F15: 2026-05-13-09.38.30.090000 | G15: USER001 | H15: 2025 | I15: 202505 | J15: 01 | K15: 100001 | L15: 2024 | M15: 01 | N15: 01 | O15: 1001 | P15: 1000000 | Q15: 50000 | R15: 5000000 | S15: 250000
B16: TC01 | C16: 0 | D16: 0 | E16: 2026-05-13-09.38.30.090000 | F16: 2026-05-13-09.38.30.090000 | G16: USER001 | H16: 2025 | I16: 202505 | J16: 01 | K16: 100002 | L16: 2024 | M16: 01 | N16: 04 | O16: 1001 | P16: 1000000 | Q16: 50000 | R16: 5000000 | S16: 250000
B17: TC01 | C17: 0 | D17: 0 | E17: 2026-05-13-09.38.30.090000 | F17: 2026-05-13-09.38.30.090000 | G17: USER001 | H17: 2025 | I17: 202505 | J17: 01 | K17: 100001 | L17: 2025 | M17: 02 | N17: 05 | O17: 1001 | P17: 1000000 | Q17: 50000 | R17: 5000000 | S17: 250000
B18: TC01 | C18: 0 | D18: 0 | E18: 2026-05-13-09.38.30.090000 | F18: 2026-05-13-09.38.30.090000 | G18: USER001 | H18: 2025 | I18: 202505 | J18: 01 | K18: 100001 | L18: 2024 | M18: 01 | N18: 06 | O18: 1001 | P18: 1000000 | Q18: 50000 | R18: 5000000 | S18: 250000
B19: TC01 | C19: 0 | D19: 0 | E19: 2026-05-13-09.38.30.090000 | F19: 2026-05-13-09.38.30.090000 | G19: USER001 | H19: 2025 | I19: 202505 | J19: 01 | K19: 100001 | L19: 2024 | M19: 01 | N19: 07 | O19: 1001 | P19: 1000000 | Q19: 50000 | R19: 5000000 | S19: 250000
B23: 業種マスタ(DAA445_GyoshuMst)
B24: 項目名称（日本語） | C24: 削除区分 | D24: 排他カウンタ | E24: 作成日時 | F24: 最終更新日時 | G24: 最終更新者ユーザーＩＤ | H24: 入力日時 | I24: 入力者ユーザーＩＤ | J24: 承認日時 | K24: 承認者ユーザーＩＤ | L24: 業種コード | M24: 適用開始日 | N24: 適用終了日 | O24: 業種名称 | P24: 業種形態区分 | Q24: 部門コード | R24: 申請番号
B25: 項目名称（英字）＊ | C25: SAKZYO_KBN | D25: HAITA_CNT | E25: SAKSE_DTM | F25: LSTUPD_DTM | G25: LSTUPD_USER_ID | H25: NYURYOKU_DTM | I25: NYURYOKU_USER_ID | J25: SHONIN_DTM | K25: SHONIN_USER_ID | L25: GYOSHU_CD | M25: TEKIYO_KAISHIBI | N25: TEKIYO_SHURYOBI | O25: GYOSHU_MEISHO | P25: GYOSHU_KEITAI_KBN | Q25: BUMON_CD | R25: SHINSEI_NO
B26: データ型 | C26: CHAR | D26: INTEGER | E26: TIMESTAMP | F26: TIMESTAMP | G26: VARCHAR | H26: TIMESTAMP | I26: VARCHAR | J26: TIMESTAMP | K26: VARCHAR | L26: VARCHAR | M26: INTEGER | N26: INTEGER | O26: VARCHAR | P26: VARCHAR | Q26: VARCHAR | R26: VARCHAR
B27: 桁数 | C27: 1 | G27: 8 | I27: 8 | K27: 8 | L27: 2 | M27: 8 | N27: 8 | O27: 30 | P27: 1 | Q27: 2 | R27: 20
B28: 小数点以下 | M28: 0 | N28: 0
B29: 符号
B30: Pｷｰ* | L30: 1 | M30: 2
B31: 初期値* | C31: 0 | D31: 0 | N31: 99991231
B32: NN* | C32: Y | D32: Y | E32: Y | F32: Y | G32: Y | H32: Y | I32: Y | L32: Y | M32: Y | N32: Y | O32: Y | P32: Y | Q32: Y
B33: TC01`05 | C33: 0 | D33: 0 | E33: 2023-10-27-10.00.00.000000 | F33: 2023-10-27-10.00.00.000000 | G33: ADMIN001 | H33: 2023-10-27-10.00.00.000000 | I33: USER0001 | J33: 2023-10-27-11.00.00.000000 | K33: APRV0001 | L33: 01 | M33: 20250404 | N33: 20261201 | O33: 共通・管理業種 | P33: 1 | Q33: 01 | R33: WF-GS-001
B38: 収支管理品目マスタ(DAA456_ShushiKanriHinmokuMst)
B39: 項目名称（日本語） | C39: 削除区分 | D39: 排他カウンタ | E39: 作成日時 | F39: 最終更新日時 | G39: 最終更新者ユーザーＩＤ | H39: 入力日時 | I39: 入力者ユーザーＩＤ | J39: 承認日時 | K39: 承認者ユーザーＩＤ | L39: 収支管理品目コード | M39: 適用開始日 | N39: 適用終了日 | O39: 収支管理品目名称 | P39: 収支管理品目略称 | Q39: 年産管理有無区分 | R39: 規格名称 | S39: 収支管理品目等級区分 | T39: 収支管理品目荷姿区分 | U39: 収支管理品目単位区分 | V39: 収支管理品目入数 | W39: 収支管理品目入数単位区分 | X39: 受払単位区分 | Y39: 棚卸資産評価区分 | Z39: 受払評価区分 | AA39: 循環棚卸区分 | AB39: 収支管理品目大分類コード | AC39: 決済条件適用品目コード | AD39: 出力制御コード | AE39: 送信元システム管理コード | AF39: 連動区分 | AG39: 申請番号
B40: 項目名称（英字）＊ | C40: SAKZYO_KBN | D40: HAITA_CNT | E40: SAKSE_DTM | F40: LSTUPD_DTM | G40: LSTUPD_USER_ID | H40: NYURYOKU_DTM | I40: NYURYOKU_USER_ID | J40: SHONIN_DTM | K40: SHONIN_USER_ID | L40: SHUSHI_KANRI_HINMOKU_CD | M40: TEKIYO_KAISHIBI | N40: TEKIYO_SHURYOBI | O40: SHUSHI_KANRI_HINMOKU_MEISHO | P40: SHUSHI_KANRI_HINMOKU_RYAKUSHO | Q40: NENSAN_KANRI_UMU_KBN | R40: KIKAKU_MEISHO | S40: SHUSHI_KANRI_HINMOKU_TOKYU_KBN | T40: SHUSHI_KANRI_HINMOKU_NISUGATA_KBN | U40: SHUSHI_KANRI_HINMOKU_TANI_KBN | V40: SHUSHI_KANRI_HINMOKU_IRISU | W40: SHUSHI_KANRI_HINMOKU_IRISU_TANI_KBN | X40: UKEHARAI_TANI_KBN | Y40: TANAOROSHI_SHISAN_HYOKA_KBN | Z40: UKEHARAI_HYOKA_KBN | AA40: JUNKAN_TANAOROSHI_KBN | AB40: SHUSHI_KANRI_HINMOKU_DAIBUNRUI_CD | AC40: KESSAI_JOKEN_TEKIYO_HINMOKU_CD | AD40: SHUTSURYOKU_SEIGYO_CD | AE40: SOSHINMOTO_SYSTEM_KANRI_CD | AF40: RENDO_KBN | AG40: SHINSEI_NO
B41: データ型 | C41: CHAR | D41: INTEGER | E41: TIMESTAMP | F41: TIMESTAMP | G41: VARCHAR | H41: TIMESTAMP | I41: VARCHAR | J41: TIMESTAMP | K41: VARCHAR | L41: VARCHAR | M41: INTEGER | N41: INTEGER | O41: VARCHAR | P41: VARCHAR | Q41: VARCHAR | R41: VARCHAR | S41: VARCHAR | T41: VARCHAR | U41: VARCHAR | V41: NUMERIC | W41: VARCHAR | X41: VARCHAR | Y41: VARCHAR | Z41: VARCHAR | AA41: VARCHAR | AB41: VARCHAR | AC41: VARCHAR | AD41: VARCHAR | AE41: VARCHAR | AF41: VARCHAR | AG41: VARCHAR
B42: 桁数 | C42: 1 | G42: 8 | I42: 8 | K42: 8 | L42: 6 | M42: 8 | N42: 8 | O42: 150 | P42: 60 | Q42: 1 | R42: 18 | S42: 3 | T42: 2 | U42: 2 | V42: 8 | W42: 2 | X42: 1 | Y42: 1 | Z42: 2 | AA42: 2 | AB42: 3 | AC42: 6 | AD42: 6 | AE42: 3 | AF42: 1 | AG42: 20
B43: 小数点以下 | M43: 0 | N43: 0 | V43: 3
B44: 符号
B45: Pｷｰ* | L45: 1 | M45: 2
B46: 初期値* | C46: 0 | D46: 0 | N46: 99991231
B47: NN* | C47: Y | D47: Y | E47: Y | F47: Y | G47: Y | H47: Y | I47: Y | L47: Y | M47: Y | N47: Y | O47: Y | P47: Y | Q47: Y | R47: Y | S47: Y | T47: Y | U47: Y | V47: Y | W47: Y | X47: Y | Y47: Y | Z47: Y | AA47: Y | AB47: Y | AC47: Y | AD47: Y | AE47: Y | AF47: Y | AG47: Y
B48: TC01`05 | C48: 0 | D48: 0 | E48: 2023-10-27-10.00.00.000000 | F48: 2023-10-27-10.00.00.000000 | G48: ADMIN001 | H48: 2023-10-27-10.00.00.000000 | I48: USER0001 | J48: 2023-10-27-11.00.00.000000 | K48: APRV0001 | L48: 100001 | M48: 20250404 | N48: 20261201 | O48: メークイン（Ｌ） | P48: ﾒｰｸｲﾝL | Q48: 1 | R48: 20kgコンテナ | S48: 001 | T48: 02 | U48: 02 | V48: 1 | W48: 02 | X48: 1 | Y48: 1 | Z48: 01 | AA48: 00 | AB48: 101 | AC48: 110001 | AD48: 000001 | AE48: JH | AF48: 1 | AG48: WF-SH-001
A49: orderby | B49: TC01 | C49: 0 | D49: 0 | E49: 2023-10-27-10.00.00.000000 | F49: 2023-10-27-10.00.00.000000 | G49: ADMIN001 | H49: 2023-10-27-10.00.00.000000 | I49: USER0001 | J49: 2023-10-27-11.00.00.000000 | K49: APRV0001 | L49: 100002 | M49: 20250404 | N49: 20261201 | O49: メークイン（Ｌ） | P49: ﾒｰｸｲﾝL | Q49: 1 | R49: 20kgコンテナ | S49: 001 | T49: 02 | U49: 02 | V49: 1 | W49: 02 | X49: 1 | Y49: 1 | Z49: 01 | AA49: 00 | AB49: 101 | AC49: 110001 | AD49: 000001 | AE49: JH | AF49: 1 | AG49: WF-SH-001
B53: 収支管理品目大分類マスタ(DAA454_ShushiKanriHinmokuDaibunruiMst)
B54: 項目名称（日本語） | C54: 削除区分 | D54: 排他カウンタ | E54: 作成日時 | F54: 最終更新日時 | G54: 最終更新者ユーザーＩＤ | H54: 入力日時 | I54: 入力者ユーザーＩＤ | J54: 承認日時 | K54: 承認者ユーザーＩＤ | L54: 収支管理品目大分類コード | M54: 適用開始日 | N54: 適用終了日 | O54: 収支管理品目大分類名称 | P54: 会計情報品目コード | Q54: 申請番号
...

Sheet テストデータ期待値（No.2)
B4: 入力 | C4: 手数料配分計算書出力検索条件DTO
B5: ケースNo | C5: 業種コード | D5: 所属コード | E5: 基準年月末日 | F5: 選択可能業種リスト | G5: 対象年月
B6: caseNo | C6: GYOSHU_CD | D6: shozokuCd | E6: kijunNengetsuMatsujitsu | F6: selectableGyoshuCdList
B7: TC01 | C7: 01 | D7: 0 | E7: 20250501 | F7: 01,02 | G7: 202505
B8: TC02 | C8: NULL | D8: 0 | E8: 20250403 | F8: 01,02 | G8: 202505
B9: TC03 | C9: NULL | D9: 1 | E9: 20261202 | F9: 99 | G9: 202505
B10: TC04 | C10: NULL | D10: 0 | E10: 20250404 | F10: NULL | G10: 202505
B11: TC05 | C11: 01 | D11: 0 | E11: 20261201 | F11: 01,02 | G11: 299912
B15: 期待値 | C15: 全道共計手数料配分計算データDtoリスト
B16: ケースNo | C16: 対象年月 | D16: 業種コード | E16: 業種名称 | F16: 会計情報品目コード | G16: 会計情報品目名称 | H16: 収支管理品目コード | I16: 収支管理品目名称 | J16: 年産 | K16: 共計次数 | L16: 配分箇所 | M16: 配分箇所名 | N16: 取扱高金額月計 | O16: 取扱高手数料月計 | P16: 取扱高金額累計 | Q16: 取扱高手数料累計
B17: caseNo | C17: taishoNengetsu | D17: gyoshuCd | E17: gyoshuMei | F17: kaikeiJohoHinmokuCd | G17: kaikeiJohoHinmokuMeisho | H17: shushiKanriHinmokuCd | I17: shushiKanriHinmokuMeisho | J17: nensan | K17: kyokeiJisu | L17: haibunKasho | M17: haibunKashoMei | N17: toriatsukaidakaKingakuGekkei | O17: toriatsukaidakaTesuryoGekkei | P17: toriatsukaidakaKingakuRuikei | Q17: toriatsukaidakaTesuryoRuikei
B18: TC01 | C18: ='テストデータDB（No.2）'!I15 -> 202505 | D18: ='テストデータDB（No.2）'!J15 -> 01 | E18: ='テストデータDB（No.2）'!O33 -> 共通・管理業種 | F18: ='テストデータDB（No.2）'!L79 -> 101 | G18: ='テストデータDB（No.2）'!O79 -> 小麦類 | H18: ='テストデータDB（No.2）'!K15 -> 100001 | I18: ='テストデータDB（No.2）'!O48 -> メークイン（Ｌ） | J18: 2024 | K18: 01 | L18: ='テストデータDB（No.2）'!L93 -> 01 | M18: ='テストデータDB（No.2）'!Q93 -> 札幌本社 | N18: ='テストデータDB（No.2）'!P15 -> 1000000 | O18: ='テストデータDB（No.2）'!Q15 -> 50000 | P18: ='テストデータDB（No.2）'!R15 -> 5000000 | Q18: ='テストデータDB（No.2）'!S15 -> 250000
B19: TC01 | C19: 202505 | D19: 01 | E19: 「対象外」 | F19: 「対象外」 | G19: 「対象外」 | H19: 100002 | I19: 「対象外」 | J19: 2024 | K19: 01 | L19: 「対象外」 | M19: 「対象外」 | N19: 「対象外」 | O19: 「対象外」 | P19: 「対象外」 | Q19: 「対象外」
B20: TC01 | C20: 202505 | D20: 01 | E20: 「対象外」 | F20: 「対象外」 | G20: 「対象外」 | H20: 100001 | I20: 「対象外」 | J20: 2025 | K20: 01 | L20: 「対象外」 | M20: 「対象外」 | N20: 「対象外」 | O20: 「対象外」 | P20: 「対象外」 | Q20: 「対象外」
B21: TC01 | C21: 202505 | D21: 01 | E21: 「対象外」 | F21: 「対象外」 | G21: 「対象外」 | H21: 100001 | I21: 「対象外」 | J21: 2024 | K21: 02 | L21: 「対象外」 | M21: 「対象外」 | N21: 「対象外」 | O21: 「対象外」 | P21: 「対象外」 | Q21: 「対象外」
B22: TC01 | C22: 202505 | D22: 01 | E22: 「対象外」 | F22: 「対象外」 | G22: 「対象外」 | H22: 100001 | I22: 「対象外」 | J22: 2024 | K22: 01 | L22: 「対象外」 | M22: 「対象外」 | N22: 「対象外」 | O22: 「対象外」 | P22: 「対象外」 | Q22: 「対象外」
B23: TC02 | C23: ='テストデータDB（No.2）'!I15 -> 202505 | D23: ='テストデータDB（No.2）'!J15 -> 01 | E23: null | F23: null | G23: null | H23: ='テストデータDB（No.2）'!K15 -> 100001 | I23: null | J23: ='テストデータDB（No.2）'!L15 -> 2024 | K23: null | L23: ='テストデータDB（No.2）'!L93 -> 01 | M23: null | N23: ='テストデータDB（No.2）'!P15 -> 1000000 | O23: ='テストデータDB（No.2）'!Q15 -> 50000 | P23: ='テストデータDB（No.2）'!R15 -> 5000000 | Q23: ='テストデータDB（No.2）'!S15 -> 250000
B24: TC03 | C24: ='テストデータDB（No.2）'!I15 -> 202505 | D24: ='テストデータDB（No.2）'!J15 -> 01 | E24: null | F24: null | G24: null | H24: ='テストデータDB（No.2）'!K15 -> 100001 | I24: null | J24: ='テストデータDB（No.2）'!L15 -> 2024 | K24: null | L24: ='テストデータDB（No.2）'!L93 -> 01 | M24: null | N24: ='テストデータDB（No.2）'!P15 -> 1000000 | O24: ='テストデータDB（No.2）'!Q15 -> 50000 | P24: ='テストデータDB（No.2）'!R15 -> 5000000 | Q24: ='テストデータDB（No.2）'!S15 -> 250000
B25: TC04 | C25: null | D25: null | E25: null | F25: null | G25: null | H25: null | I25: null | J25: null | K25: null | L25: null | M25: null | N25: null | O25: null | P25: null | Q25: null
B26: TC05 | C26: null | D26: null | E26: null | F26: null | G26: null | H26: null | I26: null | J26: null | K26: null | L26: null | M26: null | N26: null | O26: null | P26: null | Q26: null

Sheet テスト仕様（No.3)
B1: テストケースＮｏ． | C1: 1 | D1: 件数： | E1: =COUNTA(F1:CW1) -> 5 | F1: =COLUMN()-5 -> 1 | G1: =COLUMN()-5 -> 2 | H1: =COLUMN()-5 -> 3 | I1: =COLUMN()-5 -> 4 | J1: =COLUMN()-5 -> 5
C2: № | D2: テストケース条件内容
B3: テストケース条件 | C3: 1 | D3: parameterType
C4: 2 | D4: 業種コード
C5: 3 | D5: NULL以外 | F5: Y
C6: 4 | D6: NULL | G6: Y | H6: Y | I6: Y | J6: Y
C8: 5 | D8: 所属コード
C9: 6 | D9: 経理部以外 | G9: Y | H9: Y | J9: Y
C10: 7 | D10: 経理部("1") | F10: Y | I10: Y
C12: 8 | D12: 購買手数料配分計算書.直送品売上（月計） + 購買手数料配分計算書.在庫品売上（月計）
C13: 9 | D13: =0 | F13: Y | H13: Y | I13: Y | J13: Y
C14: 10 | D14: else | G14: Y
C16: 11 | D16: 購買手数料配分計算書.直送品売上（月計） + 購買手数料配分計算書.在庫品売上（月計）
C17: 12 | D17: =0 | F17: Y | H17: Y | I17: Y | J17: Y
C18: 13 | D18: else | G18: Y
C20: 14 | D20: 購買手数料配分計算書.直送品売上（月計）
C21: 15 | D21: =0 | F21: Y | H21: Y | I21: Y | J21: Y
C22: 16 | D22: else | G22: Y
C24: 17 | D24: when 購買手数料配分計算書.在庫品売上（月計）
C25: 18 | D25: =0 | F25: Y | H25: Y | I25: Y | J25: Y
C26: 19 | D26: else | G26: Y
C28: 20 | D28: 購買手数料配分計算書.直送品売上（累計） + 購買手数料配分計算書.在庫品売上（累計）
C29: 21 | D29: =0 | F29: Y | H29: Y | I29: Y | J29: Y
C30: 22 | D30: else | G30: Y
C32: 23 | D32: 購買手数料配分計算書.直送品売上（累計）
C33: 24 | D33: =0 | F33: Y | H33: Y | I33: Y | J33: Y
C34: 25 | D34: else | G34: Y
C36: 26 | D36: 購買手数料配分計算書.在庫品売上（累計）
C37: 27 | D37: =0 | F37: Y | H37: Y | I37: Y | J37: Y
C38: 28 | D38: else | G38: Y
C43: № | D43: 確認項目内容
C44: 1 | D44: resultType
C45: 3 | D45: テストデータ期待値（No.1）シートTC01 の処理結果照会Dtoと同様のデータが返却されること | F45: Y
C46: 4 | D46: テストデータ期待値（No.2）シートTC02 の処理結果照会Dtoと同様のデータが返却されること | G46: Y
C47: 5 | D47: テストデータ期待値（No.3）シートTC03 の処理結果照会Dtoと同様のデータが返却されること | H47: Y
C48: 6 | D48: テストデータ期待値（No.4）シートTC04 の処理結果照会Dtoと同様のデータが返却されること | I48: Y
C49: 7 | D49: テストデータ期待値（No.5）シートTC05 の処理結果照会Dtoと同様のデータが返却されること | J49: Y
C53: № | D53: エビデンス内容
B54: エビデンス | C54: 1 | E54: I
E55: O
...

Sheet テストデータDB（No.3）
B3: 購買手数料配分情報(DAC119_KobaiTesuryoHaibunJoho)
B4: 項目名称（日本語） | C4: 削除区分 | D4: 排他カウンタ | E4: 作成日時 | F4: 最終更新日時 | G4: 最終更新者ユーザーＩＤ | H4: 会計年度 | I4: 対象年月 | J4: 業種コード | K4: 取扱区分 | L4: 年産 | M4: 取扱組織コード | N4: 会計情報品目コード | O4: 収支管理品目大分類コード | P4: 収支管理品目コード | Q4: 指図事業所コード | R4: 一般共計区分 | S4: 直送品売上（月計） | T4: 直送品手数料（月計） | U4: 在庫品売上（月計） | V4: 在庫品手数料（月計） | W4: 供給費（月計） | X4: 直送品売上（累計） | Y4: 直送品手数料（累計） | Z4: 在庫品売上（累計） | AA4: 在庫品手数料（累計） | AB4: 供給費（累計）
B5: 項目名称（英字）＊ | C5: SAKZYO_KBN | D5: HAITA_CNT | E5: SAKSE_DTM | F5: LSTUPD_DTM | G5: LSTUPD_USER_ID | H5: KAIKEI_NENDO | I5: TAISHO_NENGETSU | J5: GYOSHU_CD | K5: TORIATSUKAI_KBN | L5: NENSAN | M5: TORIATSUKAI_SOSHIKI_CD | N5: KAIKEI_JOHO_HINMOKU_CD | O5: SHUSHI_KANRI_HINMOKU_DAIBUNRUI_CD | P5: SHUSHI_KANRI_HINMOKU_CD | Q5: SASHIZU_JIGYOSHO_CD | R5: IPPAN_KYOKEI_KBN | S5: CHOKUSOHIN_URIAGE_GEKKEI | T5: CHOKUSOHIN_TESURYO_GEKKEI | U5: ZAIKOHIN_URIAGE_GEKKEI | V5: ZAIKOHIN_TESURYO_GEKKEI | W5: KYOKYUHI_GEKKEI | X5: CHOKUSOHIN_URIAGE_RUIKEI | Y5: CHOKUSOHIN_TESURYO_RUIKEI | Z5: ZAIKOHIN_URIAGE_RUIKEI | AA5: ZAIKOHIN_TESURYO_RUIKEI | AB5: KYOKYUHI_RUIKEI
B6: データ型 | C6: CHAR | D6: INTEGER | E6: TIMESTAMP | F6: TIMESTAMP | G6: VARCHAR | H6: NUMERIC | I6: NUMERIC | J6: VARCHAR | K6: VARCHAR | L6: VARCHAR | M6: VARCHAR | N6: VARCHAR | O6: VARCHAR | P6: VARCHAR | Q6: VARCHAR | R6: VARCHAR | S6: NUMERIC | T6: NUMERIC | U6: NUMERIC | V6: NUMERIC | W6: NUMERIC | X6: NUMERIC | Y6: NUMERIC | Z6: NUMERIC | AA6: NUMERIC | AB6: NUMERIC
B7: 桁数 | C7: 1 | G7: 8 | H7: 4 | I7: 6 | J7: 2 | K7: 1 | L7: 4 | M7: 4 | N7: 3 | O7: 3 | P7: 6 | Q7: 2 | R7: 1 | S7: 13 | T7: 13 | U7: 13 | V7: 13 | W7: 13 | X7: 13 | Y7: 13 | Z7: 13 | AA7: 13 | AB7: 13
B8: 小数点以下
B9: 符号
B10: Pｷｰ* | H10: 1 | I10: 2 | J10: 3 | K10: 4 | L10: 5 | M10: 6 | P10: 7 | Q10: 8 | R10: 9
B11: 初期値* | C11: 0 | D11: 0
B12: NN* | C12: Y | D12: Y | E12: Y | F12: Y | G12: Y | H12: Y | I12: Y | J12: Y | K12: Y | L12: Y | M12: Y | N12: Y | O12: Y | P12: Y | Q12: Y | R12: Y
B13: TC01`05 | C13: 0 | D13: 0 | E13: 2026-05-14-16.37.23.225000 | F13: 2026-05-14-16.37.23.225000 | G13: USER001 | H13: 2025 | I13: 202505 | J13: 01 | K13: 101001 | L13: 2025 | M13: 1001 | N13: 1500000 | O13: 101 | P13: 0 | Q13: 01 | R13: 0 | S13: 0 | T13: 0 | U13: 0 | V13: 0 | W13: 0 | X13: 0 | Y13: 0 | Z13: 0 | AA13: 0 | AB13: 0
A14: QA | B14: TC01 | C14: 0 | D14: 0 | E14: 2026-05-14-16.37.23.225000 | F14: 2026-05-14-16.37.23.225000 | G14: USER001 | H14: 2025 | I14: 202505 | J14: 01 | K14: 101011 | L14: 2025 | M14: 1001 | N14: 1500000 | O14: 101 | P14: 0 | Q14: 01 | R14: 0 | S14: 45000 | T14: 45000 | U14: 45000 | V14: 45000 | W14: 45000 | X14: 45000 | Y14: 45000 | Z14: 45000 | AA14: 45000 | AB14: 45000
B15: TC01 | C15: 0 | D15: 0 | E15: 2026-05-14-16.37.23.225000 | F15: 2026-05-14-16.37.23.225000 | G15: USER001 | H15: 2025 | I15: 202505 | J15: 01 | K15: 101001 | L15: 2024 | M15: 1001 | N15: 1500000 | O15: 101 | P15: 0 | Q15: 01 | R15: 0 | S15: 0 | T15: 0 | U15: 0 | V15: 0 | W15: 0 | X15: 0 | Y15: 0 | Z15: 0 | AA15: 0 | AB15: 0
B16: TC01 | C16: 0 | D16: 0 | E16: 2026-05-14-16.37.23.225000 | F16: 2026-05-14-16.37.23.225000 | G16: USER001 | H16: 2025 | I16: 202505 | J16: 01 | K16: 101001 | L16: 2025 | M16: 1002 | N16: 1500000 | O16: 101 | P16: 0 | Q16: 01 | R16: 0 | S16: 0 | T16: 0 | U16: 0 | V16: 0 | W16: 0 | X16: 0 | Y16: 0 | Z16: 0 | AA16: 0 | AB16: 0
B17: TC01 | C17: 0 | D17: 0 | E17: 2026-05-14-16.37.23.225000 | F17: 2026-05-14-16.37.23.225000 | G17: USER001 | H17: 2026 | I17: 202505 | J17: 01 | K17: 101001 | L17: 2025 | M17: 1001 | N17: 1500000 | O17: 111 | P17: 0 | Q17: 01 | R17: 0 | S17: 0 | T17: 0 | U17: 0 | V17: 0 | W17: 0 | X17: 0 | Y17: 0 | Z17: 0 | AA17: 0 | AB17: 0
B18: TC01 | C18: 0 | D18: 0 | E18: 2026-05-14-16.37.23.225000 | F18: 2026-05-14-16.37.23.225000 | G18: USER001 | H18: 2026 | I18: 202505 | J18: 01 | K18: 101001 | L18: 2025 | M18: 1001 | N18: 1500000 | O18: 101 | P18: 0 | Q18: 02 | R18: 0 | S18: 0 | T18: 0 | U18: 0 | V18: 0 | W18: 0 | X18: 0 | Y18: 0 | Z18: 0 | AA18: 0 | AB18: 0
B22: 購買共計手数料配分計算データ (DAC322_KobaiKyokeiTesuryoHaibunKeisanData)
B23: 項目名称（日本語） | C23: 削除区分 | D23: 排他カウンタ | E23: 作成日時 | F23: 最終更新日時 | G23: 最終更新者ユーザーＩＤ | H23: 会計年度 | I23: 対象年月 | J23: 業種コード | K23: 年産 | L23: 会計情報品目コード | M23: 収支管理品目大分類コード | N23: 収支管理品目コード | O23: 指図事業所コード | P23: 直送品売上（月計） | Q23: 直送品手数料（月計） | R23: 在庫品売上（月計） | S23: 在庫品手数料（月計） | T23: 直送品売上（累計） | U23: 直送品手数料（累計） | V23: 在庫品売上（累計） | W23: 在庫品手数料（累計） | X23: 取扱組織コード
B24: 項目名称（英字）＊ | C24: SAKZYO_KBN | D24: HAITA_CNT | E24: SAKSE_DTM | F24: LSTUPD_DTM | G24: LSTUPD_USER_ID | H24: KAIKEI_NENDO | I24: TAISHO_NENGETSU | J24: GYOSHU_CD | K24: NENSAN | L24: KAIKEI_JOHO_HINMOKU_CD | M24: SHUSHI_KANRI_HINMOKU_DAIBUNRUI_CD | N24: SHUSHI_KANRI_HINMOKU_CD | O24: SASHIZU_JIGYOSHO_CD | P24: CHOKUSOHIN_URIAGE_GEKKEI | Q24: CHOKUSOHIN_TESURYO_GEKKEI | R24: ZAIKOHIN_URIAGE_GEKKEI | S24: ZAIKOHIN_TESURYO_GEKKEI | T24: CHOKUSOHIN_URIAGE_RUIKEI | U24: CHOKUSOHIN_TESURYO_RUIKEI | V24: ZAIKOHIN_URIAGE_RUIKEI | W24: ZAIKOHIN_TESURYO_RUIKEI | X24: TORIATSUKAI_SOSHIKI_CD
B25: データ型 | C25: CHAR | D25: INTEGER | E25: TIMESTAMP | F25: TIMESTAMP | G25: VARCHAR | H25: NUMERIC | I25: NUMERIC | J25: VARCHAR | K25: VARCHAR | L25: VARCHAR | M25: VARCHAR | N25: VARCHAR | O25: VARCHAR | P25: NUMERIC | Q25: NUMERIC | R25: NUMERIC | S25: NUMERIC | T25: NUMERIC | U25: NUMERIC | V25: NUMERIC | W25: NUMERIC | X25: VARCHAR
B26: 桁数 | C26: 1 | G26: 8 | H26: 4 | I26: 6 | J26: 2 | K26: 4 | L26: 3 | M26: 3 | N26: 6 | O26: 2 | P26: 13 | Q26: 13 | R26: 13 | S26: 13 | T26: 13 | U26: 13 | V26: 13 | W26: 13 | X26: 4
B27: 小数点以下
B28: 符号
B29: Pｷｰ* | H29: 1 | I29: 2 | J29: 3 | K29: 5 | N29: 6 | O29: 7 | X29: 4
B30: 初期値* | C30: 0 | D30: 0
B31: NN* | C31: Y | D31: Y | E31: Y | F31: Y | G31: Y | H31: Y | I31: Y | J31: Y | K31: Y | L31: Y | M31: Y | N31: Y | O31: Y | X31: Y
B32: TC01`05 | C32: 0 | D32: 0 | E32: 2026-05-13-09.38.30.090000 | F32: 2026-05-19-10.26.25.887000 | G32: USER001 | H32: 2025 | I32: 202505 | J32: 01 | K32: 2025 | L32: 101 | M32: 101 | N32: 100001 | O32: 01 | P32: 45000 | Q32: 45000 | R32: 45000 | S32: 45000 | T32: 45000 | U32: 45000 | V32: 45000 | W32: 45000 | X32: 1001
B33: TC01 | C33: 0 | D33: 0 | E33: 2026-05-13-09.38.30.090000 | F33: 2026-05-19-10.26.25.887000 | G33: USER001 | H33: 2025 | I33: 202505 | J33: 01 | K33: 2024 | L33: 101 | M33: 101 | N33: 100002 | O33: 01 | P33: 45000 | Q33: 45000 | R33: 45000 | S33: 45000 | T33: 45000 | U33: 45000 | V33: 45000 | W33: 45000 | X33: 1001
B34: TC01 | C34: 0 | D34: 0 | E34: 2026-05-13-09.38.30.090000 | F34: 2026-05-19-10.26.25.887000 | G34: USER001 | H34: 2025 | I34: 202505 | J34: 01 | K34: 2025 | L34: 101 | M34: 101 | N34: 100003 | O34: 01 | P34: 45000 | Q34: 45000 | R34: 45000 | S34: 45000 | T34: 45000 | U34: 45000 | V34: 45000 | W34: 45000 | X34: 1002
B35: TC01 | C35: 0 | D35: 0 | E35: 2026-05-13-09.38.30.090000 | F35: 2026-05-19-10.26.25.887000 | G35: USER001 | H35: 2025 | I35: 202505 | J35: 01 | K35: 2025 | L35: 101 | M35: 111 | N35: 100004 | O35: 01 | P35: 45000 | Q35: 45000 | R35: 45000 | S35: 45000 | T35: 45000 | U35: 45000 | V35: 45000 | W35: 45000 | X35: 1001
B36: TC01 | C36: 0 | D36: 0 | E36: 2026-05-13-09.38.30.090000 | F36: 2026-05-19-10.26.25.887000 | G36: USER001 | H36: 2025 | I36: 202505 | J36: 01 | K36: 2025 | L36: 101 | M36: 101 | N36: 100005 | O36: 02 | P36: 45000 | Q36: 45000 | R36: 45000 | S36: 45000 | T36: 45000 | U36: 45000 | V36: 45000 | W36: 45000 | X36: 1001
B40: 購買手数料配分計算書(middleテーブル)
B41: 項目名称（日本語） | C41: 対象年月 | D41: 業種コード | E41: 取扱区分 | F41: 年産 | G41: 取扱組織コード | H41: 収支管理品目大分類コード | I41: 指図事業所コード | J41: 直送品売上（月計） | K41: 直送品手数料（月計） | L41: 在庫品売上（月計） | M41: 在庫品手数料（月計） | N41: 供給費（月計） | O41: 直送品売上（累計） | P41: 直送品手数料（累計） | Q41: 在庫品売上（累計） | R41: 在庫品手数料（累計） | S41: 供給費（累計）
B42: 項目名称（英字）＊ | C42: TAISHO_NENGETSU | D42: GYOSHU_CD | E42: TORIATSUKAI_KBN | F42: NENSAN | G42: TORIATSUKAI_SOSHIKI_CD | H42: SHUSHI_KANRI_HINMOKU_DAIBUNRUI_CD | I42: SASHIZU_JIGYOSHO_CD | J42: CHOKUSOHIN_URIAGE_GEKKEI | K42: CHOKUSOHIN_TESURYO_GEKKEI | L42: ZAIKOHIN_URIAGE_GEKKEI | M42: ZAIKOHIN_TESURYO_GEKKEI | N42: KYOKYUHI_GEKKEI | O42: CHOKUSOHIN_URIAGE_RUIKEI | P42: CHOKUSOHIN_TESURYO_RUIKEI | Q42: ZAIKOHIN_URIAGE_RUIKEI | R42: ZAIKOHIN_TESURYO_RUIKEI | S42: KYOKYUHI_RUIKEI
A43: QA | C43: =I13 -> 202505 | D43: =J13 -> 01 | E43: =K13 -> 101001 | F43: =L13 -> 2025 | G43: =M13 -> 1001 | H43: =O13 -> 101 | I43: =Q13 -> 01 | J43: =S13 -> 0 | K43: =T13 -> 0 | L43: =U13 -> 0 | M43: =V13 -> 0 | N43: =W13 -> 0 | O43: =X13 -> 0 | P43: =Y13 -> 0 | Q43: =Z13 -> 0 | ... S43: =AB13 -> 0
C44: =I14 -> 202505 | D44: =J14 -> 01 | E44: =K14 -> 101011 | F44: =L14 -> 2025 | G44: =M14 -> 1001 | H44: =O14 -> 101 | I44: =Q14 -> 01 | J44: =S14 -> 45000 | K44: =T14 -> 45000 | L44: =U14 -> 45000 | M44: =V14 -> 45000 | N44: =W14 -> 45000 | O44: =X14 -> 45000 | P44: =Y14 -> 45000 | Q44: =Z14 -> 45000 | ... S44: =AB14 -> 45000
C45: =I15 -> 202505 | D45: =J15 -> 01 | E45: =K15 -> 101001 | F45: =L15 -> 2024 | G45: =M15 -> 1001 | H45: =O15 -> 101 | I45: =Q15 -> 01 | J45: =S15 -> 0 | K45: =T15 -> 0 | L45: =U15 -> 0 | M45: =V15 -> 0 | N45: =W15 -> 0 | O45: =X15 -> 0 | P45: =Y15 -> 0 | Q45: =Z15 -> 0 | ... S45: =AB15 -> 0
C46: =I16 -> 202505 | D46: =J16 -> 01 | E46: =K16 -> 101001 | F46: =L16 -> 2025 | G46: =M16 -> 1002 | H46: =O16 -> 101 | I46: =Q16 -> 01 | J46: =S16 -> 0 | K46: =T16 -> 0 | L46: =U16 -> 0 | M46: =V16 -> 0 | N46: =W16 -> 0 | O46: =X16 -> 0 | P46: =Y16 -> 0 | Q46: =Z16 -> 0 | ... S46: =AB16 -> 0
C47: =I17 -> 202505 | D47: =J17 -> 01 | E47: =K17 -> 101001 | F47: =L17 -> 2025 | G47: =M17 -> 1001 | H47: =O17 -> 111 | I47: =Q17 -> 01 | J47: =S17 -> 0 | K47: =T17 -> 0 | L47: =U17 -> 0 | M47: =V17 -> 0 | N47: =W17 -> 0 | O47: =X17 -> 0 | P47: =Y17 -> 0 | Q47: =Z17 -> 0 | ... S47: =AB17 -> 0
C48: =I18 -> 202505 | D48: =J18 -> 01 | E48: =K18 -> 101001 | F48: =L18 -> 2025 | G48: =M18 -> 1001 | H48: =O18 -> 101 | I48: =Q18 -> 02 | J48: =S18 -> 0 | K48: =T18 -> 0 | L48: =U18 -> 0 | M48: =V18 -> 0 | N48: =W18 -> 0 | O48: =X18 -> 0 | P48: =Y18 -> 0 | Q48: =Z18 -> 0 | ... S48: =AB18 -> 0
...

Sheet テストデータ期待値（No.3)
B4: 入力 | C4: 手数料配分計算書出力検索条件DTO
B5: ケースNo | C5: 業種コード | D5: 所属コード | E5: 基準年月末日 | F5: 選択可能業種リスト | G5: 対象年月
B6: caseNo | C6: GYOSHU_CD | D6: shozokuCd | E6: kijunNengetsuMatsujitsu | F6: selectableGyoshuCdList
B7: TC01 | C7: 01 | D7: 0 | E7: 20250501 | F7: 01,02 | G7: 202505
B8: TC02 | C8: NULL | D8: 0 | E8: 20250403 | F8: 01,02 | G8: 202505
B9: TC03 | C9: NULL | D9: 1 | E9: 20261202 | F9: 99 | G9: 202505
B10: TC04 | C10: NULL | D10: 0 | E10: 20250404 | F10: NULL | G10: 202505
B11: TC05 | C11: 01 | D11: 0 | E11: 20261201 | F11: 01,02 | G11: 299912
B12: TC06 | C12: 01 | D12: 0 | E12: NULL | F12: 01,02 | G12: NULL
B16: 期待値 | C16: 購買手数料配分計算書CSVDTOリスト
B17: ケースNo | C17: 対象年月 | D17: 業種コード | E17: 業種名 | F17: 取扱区分 | G17: 年産 | H17: 取扱箇所 | I17: 取扱箇所名 | J17: 収支管理品目大分類コード | K17: 収支管理品目大分類名称 | L17: 指図事業所コード | M17: 指図事業所名 | N17: 総売上（月計） | O17: 総手数料（月計） | P17: 総手数料率（月計） | Q17: 供給費（月計） | R17: 純益（月計） | S17: 純益率（月計） | T17: 直送品売上（月計） | U17: 直送品手数料（月計） | V17: 直送品手数料率（月計） | W17: 在庫品売上（月計） | X17: 在庫品手数料（月計） | Y17: 在庫品手数料率（月計） | Z17: 総売上（累計） | AA17: 総手数料（累計） | AB17: 総手数料率（累計） | AC17: 供給費（累計） | AD17: 純益（累計） | AE17: 純益率（累計） | AF17: 直送品売上（累計） | AG17: 直送品手数料（累計） | AH17: 直送品手数料率（累計） | AI17: 在庫品売上（累計） | AJ17: 在庫品手数料（累計） | AK17: 在庫品手数料率（累計）
B18: caseNo | C18: Integer | D18: String | E18: String | F18: String | G18: String | H18: String | I18: String | J18: String | K18: String | L18: String | M18: String | N18: BigDecimal | O18: BigDecimal | P18: BigDecimal | Q18: BigDecimal | R18: BigDecimal | S18: BigDecimal | T18: BigDecimal | U18: BigDecimal | V18: BigDecimal | W18: BigDecimal | X18: BigDecimal | Y18: BigDecimal | Z18: BigDecimal | AA18: BigDecimal | AB18: BigDecimal | AC18: BigDecimal | AD18: BigDecimal | AE18: BigDecimal | AF18: BigDecimal | AG18: BigDecimal | AH18: BigDecimal | AI18: BigDecimal | AJ18: BigDecimal | AK18: BigDecimal
B19: TC01 | C19: ='テストデータDB（No.3）'!C43 -> 202505 | D19: ='テストデータDB（No.3）'!D43 -> 01 | E19: ='テストデータDB（No.3）'!O68 -> 共通・管理業種 | F19: ='テストデータDB（No.3）'!E43 -> 101001 | G19: ='テストデータDB（No.3）'!F43 -> 2025 | H19: ='テストデータDB（No.3）'!E100 & "-" & 'テストデータDB（No.3）'!G43 -> 01-1001 | I19: ='テストデータDB（No.3）'!Q115 & " " & 'テストデータDB（No.3）'!D100 -> 札幌本社 札幌本社 | J19: ='テストデータDB（No.3）'!H43 -> 101 | K19: ='テストデータDB（No.3）'!O86 -> 馬鈴薯類 | L19: ='テストデータDB（No.3）'!I43 -> 01 | M19: ='テストデータDB（No.3）'!Q115 -> 札幌本社 | N19: 0 | O19: 0 | P19: 0 | Q19: 0 | R19: 0 | S19: 0 | T19: 0 | U19: 0 | V19: 0 | W19: 0 | X19: 0 | Y19: 0 | Z19: 0 | AA19: 0 | AB19: 0 | AC19: 0 | AD19: 0 | AE19: 0 | AF19: 0 | AG19: 0 | AH19: 0 | AI19: 0 | AJ19: 0 | AK19: 0
B20: TC01 | C20: ='テストデータDB（No.3）'!C47 -> 202505 | D20: ='テストデータDB（No.3）'!D47 -> 01 | E20: ='テストデータDB（No.3）'!O68 -> 共通・管理業種 | F20: ='テストデータDB（No.3）'!E47 -> 101001 | G20: ='テストデータDB（No.3）'!F47 -> 2025 | H20: ='テストデータDB（No.3）'!E100 & "-" & 'テストデータDB（No.3）'!G47 -> 01-1001 | I20: ='テストデータDB（No.3）'!Q115 & " " & 'テストデータDB（No.3）'!D100 -> 札幌本社 札幌本社 | J20: ='テストデータDB（No.3）'!H47 -> 111 | K20: ='テストデータDB（No.3）'!O90 -> 0 | L20: ='テストデータDB（No.3）'!I47 -> 01 | M20: ='テストデータDB（No.3）'!Q115 -> 札幌本社 | N20: 0 | O20: 0 | P20: 0 | Q20: 0 | R20: 0 | S20: 0 | T20: 0 | U20: 0 | V20: 0 | W20: 0 | X20: 0 | Y20: 0 | Z20: 0 | AA20: 0 | AB20: 0 | AC20: 0 | AD20: 0 | AE20: 0 | AF20: 0 | AG20: 0 | AH20: 0 | AI20: 0 | AJ20: 0 | AK20: 0
B21: TC01 | C21: ='テストデータDB（No.3）'!C46 -> 202505 | D21: ='テストデータDB（No.3）'!D46 -> 01 | E21: ='テストデータDB（No.3）'!O68 -> 共通・管理業種 | F21: ='テストデータDB（No.3）'!E46 -> 101001 | G21: ='テストデータDB（No.3）'!F46 -> 2025 | H21: ='テストデータDB（No.3）'!E100 & "-" & 'テストデータDB（No.3）'!G46 -> 01-1002 | I21: ='テストデータDB（No.3）'!Q115 & " " & 'テストデータDB（No.3）'!D100 -> 札幌本社 札幌本社 | J21: ='テストデータDB（No.3）'!H46 -> 101 | K21: ='テストデータDB（No.3）'!O89 -> 0 | L21: ='テストデータDB（No.3）'!I46 -> 01 | M21: ='テストデータDB（No.3）'!Q115 -> 札幌本社 | N21: 0 | O21: 0 | P21: 0 | Q21: 0 | R21: 0 | S21: 0 | T21: 0 | U21: 0 | V21: 0 | W21: 0 | X21: 0 | Y21: 0 | Z21: 0 | AA21: 0 | AB21: 0 | AC21: 0 | AD21: 0 | AE21: 0 | AF21: 0 | AG21: 0 | AH21: 0 | AI21: 0 | AJ21: 0 | AK21: 0
B22: TC01 | C22: ='テストデータDB（No.3）'!C45 -> 202505 | D22: ='テストデータDB（No.3）'!D45 -> 01 | E22: ='テストデータDB（No.3）'!O68 -> 共通・管理業種 | F22: ='テストデータDB（No.3）'!E45 -> 101001 | G22: ='テストデータDB（No.3）'!F45 -> 2024 | H22: ='テストデータDB（No.3）'!E100 & "-" & 'テストデータDB（No.3）'!G45 -> 01-1001 | I22: ='テストデータDB（No.3）'!Q115 & " " & 'テストデータDB（No.3）'!D100 -> 札幌本社 札幌本社 | J22: ='テストデータDB（No.3）'!H45 -> 101 | K22: ='テストデータDB（No.3）'!O88 -> 0 | L22: ='テストデータDB（No.3）'!I45 -> 01 | M22: ='テストデータDB（No.3）'!Q115 -> 札幌本社 | N22: 0 | O22: 0 | P22: 0 | Q22: 0 | R22: 0 | S22: 0 | T22: 0 | U22: 0 | V22: 0 | W22: 0 | X22: 0 | Y22: 0 | Z22: 0 | AA22: 0 | AB22: 0 | AC22: 0 | AD22: 0 | AE22: 0 | AF22: 0 | AG22: 0 | AH22: 0 | AI22: 0 | AJ22: 0 | AK22: 0
B23: TC01 | C23: ='テストデータDB（No.3）'!C44 -> 202505 | D23: ='テストデータDB（No.3）'!D44 -> 01 | E23: ='テストデータDB（No.3）'!O68 -> 共通・管理業種 | F23: ='テストデータDB（No.3）'!E44 -> 101011 | G23: ='テストデータDB（No.3）'!F44 -> 2025 | H23: ='テストデータDB（No.3）'!E100 & "-" & 'テストデータDB（No.3）'!G44 -> 01-1001 | I23: ='テストデータDB（No.3）'!Q115 & " " & 'テストデータDB（No.3）'!D100 -> 札幌本社 札幌本社 | J23: ='テストデータDB（No.3）'!H44 -> 101 | K23: ='テストデータDB（No.3）'!O87 -> 0 | L23: ='テストデータDB（No.3）'!I44 -> 01 | M23: ='テストデータDB（No.3）'!Q115 -> 札幌本社 | N23: 90000 | O23: 90000 | P23: 100 | Q23: 45000 | R23: 45000 | S23: 50 | T23: 45000 | U23: 45000 | V23: 100 | W23: 45000 | X23: 45000 | Y23: 100 | Z23: 90000 | AA23: 90000 | AB23: 100 | AC23: 45000 | AD23: 45000 | AE23: 50 | AF23: 45000 | AG23: 45000 | AH23: 100 | AI23: 45000 | AJ23: 45000 | AK23: 100
B24: TC01 | C24: ='テストデータDB（No.3）'!C48 -> 202505 | D24: ='テストデータDB（No.3）'!D48 -> 01 | E24: ='テストデータDB（No.3）'!O68 -> 共通・管理業種 | F24: ='テストデータDB（No.3）'!E48 -> 101001 | G24: ='テストデータDB（No.3）'!F48 -> 2025 | H24: ='テストデータDB（No.3）'!E100 & "-" & 'テストデータDB（No.3）'!G45 -> 01-1001 | I24: ='テストデータDB（No.3）'!Q115 & " " & 'テストデータDB（No.3）'!D100 -> 札幌本社 札幌本社 | J24: ='テストデータDB（No.3）'!H48 -> 101 | K24: ='テストデータDB（No.3）'!O91 -> 0 | L24: ='テストデータDB（No.3）'!I48 -> 02 | M24: ='テストデータDB（No.3）'!Q115 -> 札幌本社 | N24: 0 | O24: 0 | P24: 0 | Q24: 0 | R24: 0 | S24: 0 | T24: 0 | U24: 0 | V24: 0 | W24: 0 | X24: 0 | Y24: 0 | Z24: 0 | AA24: 0 | AB24: 0 | AC24: 0 | AD24: 0 | AE24: 0 | AF24: 0 | AG24: 0 | AH24: 0 | AI24: 0 | AJ24: 0 | AK24: 0
B26: TC01 | C26: ='テストデータDB（No.3）'!C50 -> 202505 | D26: ='テストデータDB（No.3）'!D50 -> 01 | E26: ='テストデータDB（No.3）'!O68 -> 共通・管理業種 | F26: ='テストデータDB（No.3）'!E50 -> 定数.取扱区分.共計 | G26: ='テストデータDB（No.3）'!F50 -> 2025 | H26: ='テストデータDB（No.3）'!E100 & "-" & 'テストデータDB（No.3）'!G50 -> 01-1001 | I26: ='テストデータDB（No.3）'!Q115 & " " & 'テストデータDB（No.3）'!D100 -> 札幌本社 札幌本社 | J26: ='テストデータDB（No.3）'!H50 -> 101 | K26: ='テストデータDB（No.3）'!O93 -> 0 | L26: ='テストデータDB（No.3）'!I50 -> 01 | M26: ='テストデータDB（No.3）'!Q115 -> 札幌本社 | N26: 0 | O26: 0 | P26: 0 | Q26: 0 | R26: 0 | S26: 0 | T26: 0 | U26: 0 | V26: 0 | W26: 0 | X26: 0 | Y26: 0 | Z26: 0 | AA26: 0 | AB26: 0 | AC26: 0 | AD26: 0 | AE26: 0 | AF26: 0 | AG26: 0 | AH26: 0 | AI26: 0 | AJ26: 0 | AK26: 0
B27: TC01 | C27: ='テストデータDB（No.3）'!C51 -> 202505 | D27: ='テストデータDB（No.3）'!D51 -> 01 | E27: ='テストデータDB（No.3）'!O68 -> 共通・管理業種 | F27: ='テストデータDB（No.3）'!E51 -> 定数.取扱区分.共計 | G27: ='テストデータDB（No.3）'!F51 -> 2024 | H27: ='テストデータDB（No.3）'!E100 & "-" & 'テストデータDB（No.3）'!G51 -> 01-1001 | I27: ='テストデータDB（No.3）'!Q115 & " " & 'テストデータDB（No.3）'!D100 -> 札幌本社 札幌本社 | J27: ='テストデータDB（No.3）'!H51 -> 101 | K27: ='テストデータDB（No.3）'!O94 -> 0 | L27: ='テストデータDB（No.3）'!I51 -> 01 | M27: ='テストデータDB（No.3）'!Q115 -> 札幌本社 | N27: 0 | O27: 0 | P27: 0 | Q27: 0 | R27: 0 | S27: 0 | T27: 0 | U27: 0 | V27: 0 | W27: 0 | X27: 0 | Y27: 0 | Z27: 0 | AA27: 0 | AB27: 0 | AC27: 0 | AD27: 0 | AE27: 0 | AF27: 0 | AG27: 0 | AH27: 0 | AI27: 0 | AJ27: 0 | AK27: 0
B28: TC01 | C28: ='テストデータDB（No.3）'!C52 -> 202505 | D28: ='テストデータDB（No.3）'!D52 -> 01 | E28: ='テストデータDB（No.3）'!O68 -> 共通・管理業種 | F28: ='テストデータDB（No.3）'!E52 -> 定数.取扱区分.共計 | G28: ='テストデータDB（No.3）'!F52 -> 2025 | H28: ='テストデータDB（No.3）'!E100 & "-" & 'テストデータDB（No.3）'!G52 -> 01-1002 | I28: ='テストデータDB（No.3）'!Q115 & " " & 'テストデータDB（No.3）'!D100 -> 札幌本社 札幌本社 | J28: ='テストデータDB（No.3）'!H52 -> 101 | K28: ='テストデータDB（No.3）'!O95 -> 0 | L28: ='テストデータDB（No.3）'!I52 -> 01 | M28: ='テストデータDB（No.3）'!Q115 -> 札幌本社 | N28: 0 | O28: 0 | P28: 0 | Q28: 0 | R28: 0 | S28: 0 | T28: 0 | U28: 0 | V28: 0 | W28: 0 | X28: 0 | Y28: 0 | Z28: 0 | AA28: 0 | AB28: 0 | AC28: 0 | AD28: 0 | AE28: 0 | AF28: 0 | AG28: 0 | AH28: 0 | AI28: 0 | AJ28: 0 | AK28: 0
B29: TC01 | C29: ='テストデータDB（No.3）'!C53 -> 202505 | D29: ='テストデータDB（No.3）'!D53 -> 01 | E29: ='テストデータDB（No.3）'!O68 -> 共通・管理業種 | F29: ='テストデータDB（No.3）'!E53 -> 定数.取扱区分.共計 | G29: ='テストデータDB（No.3）'!F53 -> 2025 | H29: ='テストデータDB（No.3）'!E100 & "-" & 'テストデータDB（No.3）'!G53 -> 01-1001 | I29: ='テストデータDB（No.3）'!Q115 & " " & 'テストデータDB（No.3）'!D100 -> 札幌本社 札幌本社 | J29: ='テストデータDB（No.3）'!H53 -> 111 | K29: ='テストデータDB（No.3）'!O96 -> 0 | L29: ='テストデータDB（No.3）'!I53 -> 01 | M29: ='テストデータDB（No.3）'!Q115 -> 札幌本社 | N29: 0 | O29: 0 | P29: 0 | Q29: 0 | R29: 0 | S29: 0 | T29: 0 | U29: 0 | V29: 0 | W29: 0 | X29: 0 | Y29: 0 | Z29: 0 | AA29: 0 | AB29: 0 | AC29: 0 | AD29: 0 | AE29: 0 | AF29: 0 | AG29: 0 | AH29: 0 | AI29: 0 | AJ29: 0 | AK29: 0
B30: TC01 | C30: ='テストデータDB（No.3）'!C54 -> 202505 | D30: ='テストデータDB（No.3）'!D54 -> 01 | E30: ='テストデータDB（No.3）'!O68 -> 共通・管理業種 | F30: ='テストデータDB（No.3）'!E54 -> 定数.取扱区分.共計 | G30: ='テストデータDB（No.3）'!F54 -> 2025 | H30: ='テストデータDB（No.3）'!E100 & "-" & 'テストデータDB（No.3）'!G54 -> 01-1001 | I30: ='テストデータDB（No.3）'!Q115 & " " & 'テストデータDB（No.3）'!D100 -> 札幌本社 札幌本社 | J30: ='テストデータDB（No.3）'!H54 -> 101 | K30: ='テストデータDB（No.3）'!O97 -> 0 | L30: ='テストデータDB（No.3）'!I54 -> 02 | M30: ='テストデータDB（No.3）'!Q115 -> 札幌本社 | N30: 0 | O30: 0 | P30: 0 | Q30: 0 | R30: 0 | S30: 0 | T30: 0 | U30: 0 | V30: 0 | W30: 0 | X30: 0 | Y30: 0 | Z30: 0 | AA30: 0 | AB30: 0 | AC30: 0 | AD30: 0 | AE30: 0 | AF30: 0 | AG30: 0 | AH30: 0 | AI30: 0 | AJ30: 0 | AK30: 0
B31: TC02 | C31: ='テストデータDB（No.3）'!C43 -> 202505 | D31: ='テストデータDB（No.3）'!D43 -> 01 | E31: ='テストデータDB（No.3）'!O68 -> 共通・管理業種 | F31: ='テストデータDB（No.3）'!E43 -> 101001 | G31: ='テストデータDB（No.3）'!F43 -> 2025 | H31: ='テストデータDB（No.3）'!E100 & "-" & 'テストデータDB（No.3）'!G43 -> 01-1001 | I31: ='テストデータDB（No.3）'!Q115 & " " & 'テストデータDB（No.3）'!D100 -> 札幌本社 札幌本社 | J31: ='テストデータDB（No.3）'!H43 -> 101 | K31: ='テストデータDB（No.3）'!O86 -> 馬鈴薯類 | L31: ='テストデータDB（No.3）'!I43 -> 01 | M31: ='テストデータDB（No.3）'!Q115 -> 札幌本社 | N31: 0 | O31: 0 | P31: 0 | Q31: 0 | R31: 0 | S31: 0 | T31: 0 | U31: 0 | V31: 0 | W31: 0 | X31: 0 | Y31: 0 | Z31: 0 | AA31: 0 | AB31: 0 | AC31: 0 | AD31: 0 | AE31: 0 | AF31: 0 | AG31: 0 | AH31: 0 | AI31: 0 | AJ31: 0 | AK31: 0

Sheet テストデータDB（No.x）
D2: 処理結果情報 | J2: PK | L2: PK
D3: DAA441_ShoriKekkaJoho
B4: データパターン備考 | C4: テストパターンNo | E4: 削除区分_x000D_ SAKZYO_KBN | F4: 排他カウンタ_x000D_ HAITA_CNT | G4: 作成日時_x000D_ SAKSE_DTM | H4: 最終更新日時_x000D_ LSTUPD_DTM | I4: 最終更新者ユーザーＩＤ_x000D_ LSTUPD_USER_ID | J4: ジョブＩＤ_x000D_ JOB_ID | K4: ジョブ名称_x000D_ JOB_MEISHO | L4: 開始日時_x000D_ KAISHI_DTM | M4: 終了日時_x000D_ SHURYO_DTM | N4: ステータス_x000D_ STATUS | O4: レコード件数_x000D_ RECORD_KENSU | P4: エラー件数_x000D_ ERROR_KENSU | Q4: 連動元システム管理コード_x000D_ RENDOMOTO_SYSTEM_KANRI_CD | R4: 連動先システム管理コード_x000D_ RENDOSAKI_SYSTEM_KANRI_CD
B5: ジョブ名称中間一致(トスで検索) | C5: 1 | E5: 0 | F5: 0 | G5: 45951.417 | H5: 45951.458 | I5: USER01 | J5: TEST_JOB1 | K5: テトスジョブ1 | L5: 45951.417 | M5: 45957.458 | N5: 2 | O5: 90 | P5: 10 | Q5: DAA | R5: DAB
B6: ジョブ名称前方一致(トスで検索) | C6: 1 | E6: 0 | F6: 0 | G6: 45951.417 | H6: 45951.458 | I6: USER01 | J6: TEST_JOB2 | K6: トステジョブ2 | L6: 45951.417 | M6: 45957.458 | N6: 1 | O6: 10 | P6: 90 | Q6: DAA | R6: DAB
B7: ジョブ名称後方一致(トスで検索) | C7: 1 | E7: 0 | F7: 0 | G7: 45951.417 | H7: 45951.458 | I7: USER01 | J7: TEST_JOB3 | K7: テジョブ3トス | L7: 45951.417 | M7: 45957.458 | N7: 0 | O7: 100 | P7: 0 | Q7: DAA | R7: DAB
B8: 連動元システム管理コード一致 | C8: 2 | E8: 0 | F8: 0 | G8: 45951.417 | H8: 45951.458 | I8: USER01 | J8: TEST_JOB4 | K8: テストジョブ4 | L8: 45951.917 | M8: 45957.458 | N8: 0 | O8: 100 | P8: 0 | Q8: TST | R8: DAB
B9: 連動先システム管理コード一致 | C9: 3 | E9: 0 | F9: 0 | G9: 45951.417 | H9: 45951.458 | I9: USER01 | J9: TEST_JOB5 | K9: テストジョブ5 | L9: 45951.958 | M9: 45957.458 | N9: 0 | O9: 100 | P9: 0 | Q9: DAA | R9: TST
B10: 会計コードマスタ.コードにステータスが存在しない 取得対象データ | C10: 4,5 | E10: 0 | F10: 0 | G10: 45951.417 | H10: 45951.458 | I10: USER01 | J10: TEST_JOB6 | K10: テストジョブ6 | L10: 45951.417 | M10: 45957.458 | N10: 9 | O10: 100 | P10: 0 | Q10: DAA | R10: DAB
B11: V_コードデータマスタ.コードデータコードに連動元システム管理コードが存在しない 取得対象データ | C11: 4,5 | E11: 0 | F11: 0 | G11: 45951.417 | H11: 45951.458 | I11: USER01 | J11: TEST_JOB7 | K11: テストジョブ7 | L11: 45951.417 | M11: 45957.458 | N11: 0 | O11: 100 | P11: 0 | Q11: ZZZ | R11: DAB
B12: V_コードデータマスタ.コードデータコードに連動先システム管理コードが存在しない 取得対象データ | C12: 4,5 | E12: 0 | F12: 0 | G12: 45951.417 | H12: 45951.458 | I12: USER01 | J12: TEST_JOB8 | K12: テストジョブ8 | L12: 45951.417 | M12: 45957.458 | N12: 0 | O12: 100 | P12: 0 | Q12: DAA | R12: ZZZ
B13: 削除区分="1"（[定数.削除区分.有効]以外） 取得対象外データ | C13: 4,5 | E13: 1 | F13: 0 | G13: 45951.417 | H13: 45951.458 | I13: USER01 | J13: TEST_JOB9 | K13: テストジョブ9 | L13: 45951.417 | M13: 45957.458 | N13: 0 | O13: 100 | P13: 0 | Q13: DAA | R13: DAB
B14: 対象期間日時From(開始日時より大きい) 検索条件不一致データ | C14: 4,5 | E14: 0 | F14: 0 | G14: 45951.417 | H14: 45951.458 | I14: USER01 | J14: TEST_JOB10 | K14: テストジョブ10 | L14: 45950 | M14: 45957.458 | N14: 0 | O14: 100 | P14: 0 | Q14: DAA | R14: DAB
B15: 対象期間日時From(開始日時と一致) 検索条件合致データ | C15: 4,5 | E15: 0 | F15: 0 | G15: 45951.417 | H15: 45951.458 | I15: USER01 | J15: TEST_JOB11 | K15: テストジョブ11 | L15: 45950 | M15: 45957.458 | N15: 0 | O15: 100 | P15: 0 | Q15: DAA | R15: DAB
B16: 対象期間日時From(開始日時より小さい) 検索条件合致データ | C16: 4,5 | E16: 0 | F16: 0 | G16: 45951.417 | H16: 45951.458 | I16: USER01 | J16: TEST_JOB12 | K16: テストジョブ12 | L16: 45950 | M16: 45957.458 | N16: 0 | O16: 100 | P16: 0 | Q16: DAA | R16: DAB
B17: 対象期間日時From(終了日時より小さい) 検索条件合致データ | C17: 4,5 | E17: 0 | F17: 0 | G17: 45951.417 | H17: 45951.458 | I17: USER01 | J17: TEST_JOB13 | K17: テストジョブ13 | L17: 45951.417 | M17: 45958 | N17: 0 | O17: 100 | P17: 0 | Q17: DAA | R17: DAB
B18: 対象期間日時From(終了日時と一致) 検索条件不一致データ | C18: 4,5 | E18: 0 | F18: 0 | G18: 45951.417 | H18: 45951.458 | I18: USER01 | J18: TEST_JOB14 | K18: テストジョブ14 | L18: 45951.417 | M18: 45958 | N18: 0 | O18: 100 | P18: 0 | Q18: DAA | R18: DAB
B19: 対象期間日時From(終了日時より大きい) 検索条件不一致データ | C19: 4,5 | E19: 0 | F19: 0 | G19: 45951.417 | H19: 45951.458 | I19: USER01 | J19: TEST_JOB15 | K19: テストジョブ15 | L19: 45951.417 | M19: 45958 | N19: 0 | O19: 100 | P19: 0 | Q19: DAA | R19: DAB
B20: ステータス="2"（[定数.処理結果ステータス.警告]） | C20: 6,9,10 | E20: 0 | F20: 0 | G20: 45951.417 | H20: 45951.458 | I20: USER01 | J20: TEST_JOB16 | K20: テストジョブ16 | L20: 45952.083 | M20: 45957.458 | N20: 2 | O20: 90 | P20: 10 | Q20: DAA | R20: DAB
B21: ステータス="1"（[定数.処理結果ステータス.エラー]） | C21: 7,8,9,10 | E21: 0 | F21: 0 | G21: 45951.417 | H21: 45951.458 | I21: USER01 | J21: TEST_JOB17 | K21: テストジョブ17 | L21: 45952.042 | M21: 45957.458 | N21: 1 | O21: 10 | P21: 90 | Q21: DAA | R21: DAB
B22: ステータス="0"（[定数.処理結果ステータス.成功] ） | C22: 8,10 | E22: 0 | F22: 0 | G22: 45951.417 | H22: 45951.458 | I22: USER01 | J22: TEST_JOB18 | K22: テストジョブ18 | L22: 45952 | M22: 45957.458 | N22: 0 | O22: 100 | P22: 0 | Q22: DAA | R22: DAB
D26: 会計コードマスタ | J26: PK | N26: PK | O26: PK
D27: DAA425_KaikeiCdMst
B28: データパターン備考 | C28: 対象テストNo | E28: 削除区分_x000D_ SAKZYO_KBN | F28: 排他カウンタ_x000D_ HAITA_CNT | G28: 作成日時_x000D_ SAKSE_DTM | H28: 最終更新日時_x000D_ LSTUPD_DTM | I28: 最終更新者ユーザーＩＤ_x000D_ LSTUPD_USER_ID | J28: コード分類_x000D_ CD_BUNRUI | K28: コード分類名称_x000D_ CD_BUNRUI_MEISHO | L28: 桁数_x000D_ KETASU | M28: 摘要_x000D_ TEKIYO | N28: コード_x000D_ CD | O28: 適用開始日_x000D_ TEKIYO_KAISHIBI | P28: 適用終了日_x000D_ TEKIYO_SHURYOBI | Q28: 名称_x000D_ MEISHO | R28: 英語名称_x000D_ EIGO_MEISHO | S28: 属性０１_x000D_ ZOKUSEI_01 | T28: 属性０２_x000D_ ZOKUSEI_02 | U28: 属性０３_x000D_ ZOKUSEI_03 | V28: 属性０４_x000D_ ZOKUSEI_04 | W28: 属性０５_x000D_ ZOKUSEI_05 | X28: 属性０６_x000D_ ZOKUSEI_06 | Y28: 属性０７_x000D_ ZOKUSEI_07 | Z28: 属性０８_x000D_ ZOKUSEI_08 | AA28: 属性０９_x000D_ ZOKUSEI_09 | AB28: 属性１０_x000D_ ZOKUSEI_10 | AC28: 属性１１_x000D_ ZOKUSEI_11 | AD28: 属性１２_x000D_ ZOKUSEI_12 | AE28: 属性１３_x000D_ ZOKUSEI_13 | AF28: 属性１４_x000D_ ZOKUSEI_14 | AG28: 属性１５_x000D_ ZOKUSEI_15 | AH28: 属性１６_x000D_ ZOKUSEI_16 | AI28: 属性１７_x000D_ ZOKUSEI_17 | AJ28: 属性１８_x000D_ ZOKUSEI_18 | AK28: 属性１９_x000D_ ZOKUSEI_19 | AL28: 属性２０_x000D_ ZOKUSEI_20 | AM28: 属性２１_x000D_ ZOKUSEI_21 | AN28: 属性２２_x000D_ ZOKUSEI_22 | AO28: 属性２３_x000D_ ZOKUSEI_23 | AP28: 属性２４_x000D_ ZOKUSEI_24 | AQ28: 属性２５_x000D_ ZOKUSEI_25 | AR28: 属性２６_x000D_ ZOKUSEI_26 | AS28: 属性２７_x000D_ ZOKUSEI_27 | AT28: 属性２８_x000D_ ZOKUSEI_28 | AU28: 属性２９_x000D_ ZOKUSEI_29 | AV28: 属性３０_x000D_ ZOKUSEI_30
B29: 正常（成功） 対象期間From(適用開始日と一致) 検索条件合致データ | C29: 1~10 | E29: 0 | F29: 0 | G29: 46128.594 | H29: 46128.594 | I29: ADMIN | J29: 100001 | K29: 処理結果ステータス | L29: 1 | M29: « NULL » | N29: 0 | O29: 20251020 | P29: 20251231 | Q29: 成功 | R29: SUCCESS | S29: « NULL » | T29: « NULL » | U29: « NULL » | V29: « NULL » | W29: « NULL » | X29: « NULL » | Y29: « NULL » | Z29: « NULL » | AA29: « NULL » | AB29: « NULL » | AC29: « NULL » | AD29: « NULL » | AE29: « NULL » | AF29: « NULL » | AG29: « NULL » | AH29: « NULL » | AI29: « NULL » | AJ29: « NULL » | AK29: « NULL » | AL29: « NULL » | AM29: « NULL » | AN29: « NULL » | AO29: « NULL » | AP29: « NULL » | AQ29: « NULL » | AR29: « NULL » | AS29: « NULL » | AT29: « NULL » | AU29: « NULL » | AV29: « NULL »
B30: 正常（エラー） 対象期間From(適用終了日と一致) 検索条件合致データ | C30: 1~10 | E30: 0 | F30: 0 | G30: 46128.594 | H30: 46128.594 | I30: ADMIN | J30: 100001 | K30: 処理結果ステータス | L30: 1 | M30: « NULL » | N30: 1 | O30: 20251001 | P30: 20251020 | Q30: エラー | R30: ERROR | S30: « NULL » | T30: « NULL » | U30: « NULL » | V30: « NULL » | W30: « NULL » | X30: « NULL » | Y30: « NULL » | Z30: « NULL » | AA30: « NULL » | AB30: « NULL » | AC30: « NULL » | AD30: « NULL » | AE30: « NULL » | AF30: « NULL » | AG30: « NULL » | AH30: « NULL » | AI30: « NULL » | AJ30: « NULL » | AK30: « NULL » | AL30: « NULL » | AM30: « NULL » | AN30: « NULL » | AO30: « NULL » | AP30: « NULL » | AQ30: « NULL » | AR30: « NULL » | AS30: « NULL » | AT30: « NULL » | AU30: « NULL » | AV30: « NULL »
B31: 正常（警告） 対象期間From(中間値) 検索条件合致データ | C31: 1~10 | E31: 0 | F31: 0 | G31: 46128.594 | H31: 46128.594 | I31: ADMIN | J31: 100001 | K31: 処理結果ステータス | L31: 1 | M31: « NULL » | N31: 2 | O31: 20251001 | P31: 20251031 | Q31: 警告 | R31: WARNING | S31: « NULL » | T31: « NULL » | U31: « NULL » | V31: « NULL » | W31: « NULL » | X31: « NULL » | Y31: « NULL » | Z31: « NULL » | AA31: « NULL » | AB31: « NULL » | AC31: « NULL » | AD31: « NULL » | AE31: « NULL » | AF31: « NULL » | AG31: « NULL » | AH31: « NULL » | AI31: « NULL » | AJ31: « NULL » | AK31: « NULL » | AL31: « NULL » | AM31: « NULL » | AN31: « NULL » | AO31: « NULL » | AP31: « NULL » | AQ31: « NULL » | AR31: « NULL » | AS31: « NULL » | AT31: « NULL » | AU31: « NULL » | AV31: « NULL »
B32: 対象期間From(過去のデータ) 検索条件不一致データ | C32: 1~10 | E32: 0 | F32: 0 | G32: 46128.594 | H32: 46128.594 | I32: ADMIN | J32: 100001 | K32: 処理結果ステータス | L32: 1 | M32: « NULL » | N32: 0 | O32: 20251001 | P32: 20251019 | Q32: 成功 | R32: SUCCESS | S32: « NULL » | T32: « NULL » | U32: « NULL » | V32: « NULL » | W32: « NULL » | X32: « NULL » | Y32: « NULL » | Z32: « NULL » | AA32: « NULL » | AB32: « NULL » | AC32: « NULL » | AD32: « NULL » | AE32: « NULL » | AF32: « NULL » | AG32: « NULL » | AH32: « NULL » | AI32: « NULL » | AJ32: « NULL » | AK32: « NULL » | AL32: « NULL » | AM32: « NULL » | AN32: « NULL » | AO32: « NULL » | AP32: « NULL » | AQ32: « NULL » | AR32: « NULL » | AS32: « NULL » | AT32: « NULL » | AU32: « NULL » | AV32: « NULL »
B33: 対象期間From(未来のデータ) 検索条件不一致データ | C33: 1~10 | E33: 0 | F33: 0 | G33: 46128.594 | H33: 46128.594 | I33: ADMIN | J33: 100001 | K33: 処理結果ステータス | L33: 1 | M33: « NULL » | N33: 0 | O33: 20251021 | P33: 99991231 | Q33: 成功 | R33: SUCCESS | S33: « NULL » | T33: « NULL » | U33: « NULL » | V33: « NULL » | W33: « NULL » | X33: « NULL » | Y33: « NULL » | Z33: « NULL » | AA33: « NULL » | AB33: « NULL » | AC33: « NULL » | AD33: « NULL » | AE33: « NULL » | AF33: « NULL » | AG33: « NULL » | AH33: « NULL » | AI33: « NULL » | AJ33: « NULL » | AK33: « NULL » | AL33: « NULL » | AM33: « NULL » | AN33: « NULL » | AO33: « NULL » | AP33: « NULL » | AQ33: « NULL » | AR33: « NULL » | AS33: « NULL » | AT33: « NULL » | AU33: « NULL » | AV33: « NULL »
B34: 削除区分="1"（[定数.削除区分.有効]以外） 取得対象外データ | C34: 1~10 | E34: 1 | F34: 0 | G34: 46128.594 | H34: 46128.594 | I34: ADMIN | J34: 100001 | K34: 処理結果ステータス | L34: 1 | M34: « NULL » | N34: 1 | O34: 20251002 | P34: 20251231 | Q34: エラー | R34: ERROR | S34: « NULL » | T34: « NULL » | U34: « NULL » | V34: « NULL » | W34: « NULL » | X34: « NULL » | Y34: « NULL » | Z34: « NULL » | AA34: « NULL » | AB34: « NULL » | AC34: « NULL » | AD34: « NULL » | AE34: « NULL » | AF34: « NULL » | AG34: « NULL » | AH34: « NULL » | AI34: « NULL » | AJ34: « NULL » | AK34: « NULL » | AL34: « NULL » | AM34: « NULL » | AN34: « NULL » | AO34: « NULL » | AP34: « NULL » | AQ34: « NULL » | AR34: « NULL » | AS34: « NULL » | AT34: « NULL » | AU34: « NULL » | AV34: « NULL »
B35: コード分類="999999"（[定数.コード分類.処理結果ステータス] 以外） 取得対象外データ | C35: 1~10 | E35: 0 | F35: 0 | G35: 46128.594 | H35: 46128.594 | I35: ADMIN | J35: 999999 | K35: 処理結果ステータス | L35: 1 | M35: « NULL » | N35: 2 | O35: 20251002 | P35: 20251231 | Q35: 警告 | R35: WARNING | S35: « NULL » | T35: « NULL » | U35: « NULL » | V35: « NULL » | W35: « NULL » | X35: « NULL » | Y35: « NULL » | Z35: « NULL » | AA35: « NULL » | AB35: « NULL » | AC35: « NULL » | AD35: « NULL » | AE35: « NULL » | AF35: « NULL » | AG35: « NULL » | AH35: « NULL » | AI35: « NULL » | AJ35: « NULL » | AK35: « NULL » | AL35: « NULL » | AM35: « NULL » | AN35: « NULL » | AO35: « NULL » | AP35: « NULL » | AQ35: « NULL » | AR35: « NULL » | AS35: « NULL » | AT35: « NULL » | AU35: « NULL » | AV35: « NULL »
D40: V_コードデータマスタ | N40: PK | O40: PK | P40: PK
D41: V_AQA062_CddatMst
B42: データパターン備考 | C42: 対象テストNo | E42: 削除区分_x000D_ SAKZYO_KBN | F42: 排他カウンタ_x000D_ HAITA_CNT | G42: 作成日時_x000D_ SAKSE_DTM | H42: 最終更新日時_x000D_ LSTUPD_DTM | I42: 最終更新者ユーザーID_x000D_ LSTUPD_USER_ID | J42: 入力日時_x000D_ NYURYOKU_DTM | K42: 入力者ユーザーID_x000D_ NYURYOKU_USER_ID | L42: 承認日時_x000D_ SHONIN_DTM | M42: 承認者ユーザーID_x000D_ SHONIN_USER_ID | N42: コード種別コード_x000D_ CDSBT_CD | O42: コードデータコード_x000D_ CDDAT_CD | P42: 適用開始年月日_x000D_ TEKIYO_KAISHIBI | Q42: 適用終了年月日_x000D_ TEKIYO_SHURYOBI | R42: コード名称（漢字）_x000D_ CODE_MEI_KJ | S42: コード名称（カナ）_x000D_ CODE_MEI_KN | T42: コード名称（英数）_x000D_ CODE_MEI_ES
B43: 正常 対象期間From(適用開始年月日と一致) 検索条件合致データ | C43: 1~10 | E43: 0 | F43: 0 | G43: 46128.596 | H43: 46128.596 | I43: ADMIN | J43: 46128.596 | K43: ADMIN | L43: 46128.596 | M43: ADMIN | N43: 100002 | O43: DAA | P43: 20251020 | Q43: 20251231 | R43: 統合会計共通 | S43: ﾄｳｺﾞｳｶｲｹｲｷｮｳﾂｳ | T43: DAA
B44: 正常 対象期間From(適用終了年月日と一致) 検索条件合致データ | C44: 1~10 | E44: 0 | F44: 0 | G44: 46128.596 | H44: 46128.596 | I44: ADMIN | J44: 46128.596 | K44: ADMIN | L44: 46128.596 | M44: ADMIN | N44: 100002 | O44: DAB | P44: 20251001 | Q44: 20251020 | R44: 会計統合システム | S44: ｶｲｹｲﾄｳｺﾞｳｼｽﾃﾑ | T44: DAB
B45: 正常 （連動元システム管理コード、連動先システム管理コード一致） 対象期間From(中間値) 検索条件合致データ | C45: 2,3 | E45: 0 | F45: 0 | G45: 46128.596 | H45: 46128.596 | I45: ADMIN | J45: 46128.596 | K45: ADMIN | L45: 46128.596 | M45: ADMIN | N45: 100002 | O45: TST | P45: 20251001 | Q45: 20251031 | R45: 連動元システム管理コードテスト | S45: ﾚﾝﾄﾞｳﾓﾄｼｽﾃﾑｶﾝﾘｺｰﾄﾞﾃｽﾄ | T45: TST
B46: 対象期間From(過去のデータ) 検索条件不一致データ | C46: 1~10 | E46: 0 | F46: 0 | G46: 46128.596 | H46: 46128.596 | I46: ADMIN | J46: 46128.596 | K46: ADMIN | L46: 46128.596 | M46: ADMIN | N46: 100002 | O46: DAA | P46: 20251002 | Q46: 20251019 | R46: 統合会計共通 | S46: ﾄｳｺﾞｳｶｲｹｲｷｮｳﾂｳ | T46: DAA
B47: 対象期間From(未来のデータ) 検索条件不一致データ | C47: 1~10 | E47: 0 | F47: 0 | G47: 46128.596 | H47: 46128.596 | I47: ADMIN | J47: 46128.596 | K47: ADMIN | L47: 46128.596 | M47: ADMIN | N47: 100002 | O47: DAB | P47: 20251021 | Q47: 20251231 | R47: 会計統合システム | S47: ｶｲｹｲﾄｳｺﾞｳｼｽﾃﾑ | T47: DAB
B48: 削除区分="1"（[定数.削除区分.有効]以外） 取得対象外データ | C48: 1~10 | E48: 1 | F48: 0 | G48: 46128.596 | H48: 46128.596 | I48: ADMIN | J48: 46128.596 | K48: ADMIN | L48: 46128.596 | M48: ADMIN | N48: 100002 | O48: DAA | P48: 20251003 | Q48: 20251231 | R48: 統合会計共通 | S48: ﾄｳｺﾞｳｶｲｹｲｷｮｳﾂｳ | T48: DAA
...
